INFO:aio_pika.robust_connection:Connection to amqp://guest:******@localhost:5672// closed. Reconnecting after 5 seconds.
ERROR:asyncio:Task exception was never retrieved
future: <Task finished name='Task-1' coro=<RabbitMQClient.consume() done, defined at c:\Rafal\Kodowanie\ISI\isi-projekt\riot-service\rabbit_client.py:131> exception=<AMQPConnectionError: (22, 'Komputer zdalny odrzuci³ po³¹czenie sieciowe', None, 1225, None)>>
Traceback (most recent call last):
  File "C:\Users\lordw\AppData\Local\Programs\Python\Python310\lib\site-packages\aiormq\connection.py", line 455, in connect
    reader, writer = await asyncio.open_connection(
  File "C:\Users\lordw\AppData\Local\Programs\Python\Python310\lib\asyncio\streams.py", line 47, in open_connection
    transport, _ = await loop.create_connection(
  File "C:\Users\lordw\AppData\Local\Programs\Python\Python310\lib\asyncio\base_events.py", line 1060, in create_connection
    raise exceptions[0]
  File "C:\Users\lordw\AppData\Local\Programs\Python\Python310\lib\asyncio\base_events.py", line 1040, in create_connection
    sock = await self._connect_sock(
  File "C:\Users\lordw\AppData\Local\Programs\Python\Python310\lib\asyncio\base_events.py", line 954, in _connect_sock
    await self.sock_connect(sock, address)
  File "C:\Users\lordw\AppData\Local\Programs\Python\Python310\lib\asyncio\proactor_events.py", line 704, in sock_connect
    return await self._proactor.connect(sock, address)
  File "C:\Users\lordw\AppData\Local\Programs\Python\Python310\lib\asyncio\windows_events.py", line 812, in _poll
    value = callback(transferred, key, ov)
  File "C:\Users\lordw\AppData\Local\Programs\Python\Python310\lib\asyncio\windows_events.py", line 599, in finish_connect
    ov.getresult()
ConnectionRefusedError: [WinError 1225] Komputer zdalny odrzuci³ po³¹czenie sieciowe

The above exception was the direct cause of the following exception:

Traceback (most recent call last):
  File "c:\Rafal\Kodowanie\ISI\isi-projekt\riot-service\rabbit_client.py", line 132, in consume
    await self.connect_and_consume()
  File "c:\Rafal\Kodowanie\ISI\isi-projekt\riot-service\rabbit_client.py", line 72, in connect_and_consume
    self.connection = await connect_robust(host="localhost", port=5672, loop=self.loop)
  File "C:\Users\lordw\AppData\Local\Programs\Python\Python310\lib\site-packages\aio_pika\robust_connection.py", line 340, in connect_robust
    await connection.connect(timeout=timeout)
  File "C:\Users\lordw\AppData\Local\Programs\Python\Python310\lib\site-packages\aio_pika\robust_connection.py", line 186, in connect
    await self.__fail_fast_future
  File "C:\Users\lordw\AppData\Local\Programs\Python\Python310\lib\site-packages\aio_pika\robust_connection.py", line 141, in __connection_factory
    await Connection.connect(self, self.__connect_timeout)
  File "C:\Users\lordw\AppData\Local\Programs\Python\Python310\lib\site-packages\aio_pika\connection.py", line 118, in connect
    self.transport = await UnderlayConnection.connect(
  File "C:\Users\lordw\AppData\Local\Programs\Python\Python310\lib\site-packages\aio_pika\abc.py", line 671, in connect
    connection = await cls.make_connection(
  File "C:\Users\lordw\AppData\Local\Programs\Python\Python310\lib\site-packages\aio_pika\abc.py", line 659, in make_connection
    connection: aiormq.abc.AbstractConnection = await asyncio.wait_for(
  File "C:\Users\lordw\AppData\Local\Programs\Python\Python310\lib\asyncio\tasks.py", line 408, in wait_for
    return await fut
  File "C:\Users\lordw\AppData\Local\Programs\Python\Python310\lib\site-packages\aiormq\connection.py", line 918, in connect
    await connection.connect(client_properties or {})
  File "C:\Users\lordw\AppData\Local\Programs\Python\Python310\lib\site-packages\aiormq\base.py", line 164, in wrap
    return await self.create_task(func(self, *args, **kwargs))
  File "C:\Users\lordw\AppData\Local\Programs\Python\Python310\lib\site-packages\aiormq\abc.py", line 44, in __inner
    return await self.task
  File "C:\Users\lordw\AppData\Local\Programs\Python\Python310\lib\site-packages\aiormq\connection.py", line 462, in connect
    raise AMQPConnectionError(*e.args) from e
aiormq.exceptions.AMQPConnectionError: [WinError 1225] Komputer zdalny odrzuci³ po³¹czenie sieciowe
